<?xml version="1.0" ?>
<!-- =================================================================================== -->
<!-- |    This document was autogenerated by xacro from /builds/airbot-play/control/arm-control/models/airbot_play_with_gripper.urdf.xacro | -->
<!-- |    EDITING THIS FILE BY HAND IS NOT RECOMMENDED                                 | -->
<!-- =================================================================================== -->
<!-- This URDF was automatically created by SolidWorks to URDF Exporter! Originally created by Stephen Brawner (brawner@gmail.com) 
     Commit Version: 1.6.0-4-g7f85cfe  Build Version: 1.6.7995.38578
     For more information, please see http://wiki.ros.org/sw_urdf_exporter -->
<robot name="airbot_play">
  <link name="base_link">
    <visual>
      <origin rpy="0 0 0" xyz="0 0 0"/>
      <geometry>
        <mesh filename="package://airbot/meshes/airbot_play_v2_1/base_link.STL"/>
      </geometry>
      <material name="">
        <color rgba="0.75294 0.75294 0.75294 1"/>
      </material>
    </visual>
    <collision>
      <origin rpy="0 0 0" xyz="0 0 0"/>
      <geometry>
        <mesh filename="package://airbot/meshes/airbot_play_v2_1/base_link.STL"/>
      </geometry>
    </collision>
  </link>
  <link name="link1">
    <inertial>
      <origin rpy="0 0 0" xyz="7.9126E-05 -0.002527 -0.0041359"/>
      <mass value="0.5571"/>
      <inertia ixx="0.0003462" ixy="0" ixz="-1.4E-06" iyy="0.0002863" iyz="-1.1E-06" izz="0.0003255"/>
    </inertial>
    <visual>
      <origin rpy="0 0 0" xyz="0 0 0"/>
      <geometry>
        <mesh filename="package://airbot/meshes/airbot_play_v2_1/link1.STL"/>
      </geometry>
      <material name="">
        <color rgba="0.89804 0.91765 0.92941 1"/>
      </material>
    </visual>
    <collision>
      <origin rpy="0 0 0" xyz="0 0 0"/>
      <geometry>
        <mesh filename="package://airbot/meshes/airbot_play_v2_1/link1.STL"/>
      </geometry>
    </collision>
  </link>
  <joint name="joint1" type="revolute">
    <origin rpy="0 0 0" xyz="0 0 0.1172"/>
    <parent link="base_link"/>
    <child link="link1"/>
    <axis xyz="0 0 1"/>
    <limit effort="18" lower="-3.14" upper="2.09" velocity="3.14"/>
  </joint>
  <link name="link2">
    <inertial>
      <origin rpy="0 0 0" xyz="0.22493 0.0047721 0.008023"/>
      <mass value="0.64621"/>
      <inertia ixx="0.0004901" ixy="0.0005229" ixz="-0.0002434" iyy="0.0050391" iyz="-2.95E-05" izz="0.00195052"/>
    </inertial>
    <visual>
      <origin rpy="0 0 0" xyz="0 0 0"/>
      <geometry>
        <mesh filename="package://airbot/meshes/airbot_play_v2_1/link2.STL"/>
      </geometry>
      <material name="">
        <color rgba="0.75294 0.75294 0.75294 1"/>
      </material>
    </visual>
    <collision>
      <origin rpy="0 0 0" xyz="0 0 0"/>
      <geometry>
        <mesh filename="package://airbot/meshes/airbot_play_v2_1/link2.STL"/>
      </geometry>
    </collision>
  </link>
  <joint name="joint2" type="revolute">
    <origin rpy="1.5708 -2.7549 0" xyz="0 0 0"/>
    <parent link="link1"/>
    <child link="link2"/>
    <axis xyz="0 0 1"/>
    <limit effort="18" lower="-2.96" upper="0.17" velocity="3.14"/>
  </joint>
  <link name="link3">
    <inertial>
      <origin rpy="0 0 0" xyz="0.20055 -5.5576E-05 0.0019184"/>
      <mass value="0.44556"/>
      <inertia ixx="0.000167" ixy="-4E-07" ixz="-0.0001263" iyy="0.0006727" iyz="-1E-07" izz="0.00060895"/>
    </inertial>
    <visual>
      <origin rpy="0 0 0" xyz="0 0 0"/>
      <geometry>
        <mesh filename="package://airbot/meshes/airbot_play_v2_1/link3.STL"/>
      </geometry>
      <material name="">
        <color rgba="0.75294 0.75294 0.75294 1"/>
      </material>
    </visual>
    <collision>
      <origin rpy="0 0 0" xyz="0 0 0"/>
      <geometry>
        <mesh filename="package://airbot/meshes/airbot_play_v2_1/link3.STL"/>
      </geometry>
    </collision>
  </link>
  <joint name="joint3" type="revolute">
    <origin rpy="0 0 -2.7548" xyz="0.27009 0 0"/>
    <parent link="link2"/>
    <child link="link3"/>
    <axis xyz="0 0 1"/>
    <limit effort="18" lower="-0.087" upper="3.14" velocity="3.14"/>
  </joint>
  <link name="link4">
    <inertial>
      <origin rpy="0 0 0" xyz="0.0015 0.00040412 -0.002328"/>
      <mass value="0.345876"/>
      <inertia ixx="0.0004235" ixy="0" ixz="4.7E-06" iyy="0.00012" iyz="-1E-07" izz="0.0001269"/>
    </inertial>
    <visual>
      <origin rpy="0 0 0" xyz="0 0 0"/>
      <geometry>
        <mesh filename="package://airbot/meshes/airbot_play_v2_1/link4.STL"/>
      </geometry>
      <material name="">
        <color rgba="1 1 1 1"/>
      </material>
    </visual>
    <collision>
      <origin rpy="0 0 0" xyz="0 0 0"/>
      <geometry>
        <mesh filename="package://airbot/meshes/airbot_play_v2_1/link4.STL"/>
      </geometry>
    </collision>
  </link>
  <joint name="joint4" type="revolute">
    <origin rpy="3.1416 -1.5708 0" xyz="0.30854 0 0"/>
    <parent link="link3"/>
    <child link="link4"/>
    <axis xyz="0 0 -1"/>
    <limit effort="3" lower="-2.96" upper="2.96" velocity="6.28"/>
  </joint>
  <link name="link5">
    <inertial>
      <origin rpy="0 0 0" xyz="8.3328E-06 0.026148 0.002525"/>
      <mass value="0.186636"/>
      <inertia ixx="0.0001825" ixy="0" ixz="-3.29E-05" iyy="0.0004677" iyz="0" izz="0.0004286"/>
    </inertial>
    <visual>
      <origin rpy="0 0 0" xyz="0 0 0"/>
      <geometry>
        <mesh filename="package://airbot/meshes/airbot_play_v2_1/link5.STL"/>
      </geometry>
      <material name="">
        <color rgba="0.89804 0.91765 0.92941 1"/>
      </material>
    </visual>
    <collision>
      <origin rpy="0 0 0" xyz="0 0 0"/>
      <geometry>
        <mesh filename="package://airbot/meshes/airbot_play_v2_1/link5.STL"/>
      </geometry>
    </collision>
  </link>
  <joint name="joint5" type="revolute">
    <origin rpy="1.5708 0 0" xyz="0 0 0"/>
    <parent link="link4"/>
    <child link="link5"/>
    <axis xyz="0 0 -1"/>
    <limit effort="3" lower="-1.74" upper="1.74" velocity="6.28"/>
  </joint>
  <link name="gripper_base">
    <inertial>
      <origin rpy="0 0 0" xyz="0.020482 2.5483E-05 -0.079685"/>
      <mass value="0.40081"/>
      <inertia ixx="5E-05" ixy="0" ixz="0" iyy="0.00206" iyz="0" izz="0.0011889"/>
    </inertial>
    <visual>
      <origin rpy="0 0 0" xyz="0 0 0"/>
      <geometry>
        <mesh filename="package://airbot/meshes/airbot_gripper_2/gripper_base.STL"/>
      </geometry>
      <material name="">
        <color rgba="0.69804 0.69804 0.69804 1"/>
      </material>
    </visual>
    <collision>
      <origin rpy="0 0 0" xyz="0 0 0"/>
      <geometry>
        <mesh filename="package://airbot/meshes/airbot_gripper_2/gripper_base.STL"/>
      </geometry>
    </collision>
  </link>
  <joint name="joint_parent" type="revolute">
    <origin rpy="-1.5708 1.5708 0" xyz="0 0.23645 0"/> 
    <parent link="link5"/>
    <child link="gripper_base"/>
    <axis xyz="0 0 -1"/>
    <limit effort="3" lower="-3.14" upper="3.14" velocity="6.28"/>
  </joint>
 <!-- <link name="finger_left">
    <inertial>
      <origin rpy="0 0 0" xyz="-0.049039 -0.0096764 0.00038868"/>
      <mass value="0.061803"/>
      <inertia ixx="1.8946E-05" ixy="-1.3168E-06" ixz="-6.5528E-07" iyy="2.7277E-05" iyz="-2.0801E-07" izz="1.1981E-05"/>
    </inertial>
    <visual>
      <origin rpy="0 0 0" xyz="0 0 0"/>
      <geometry>
        <mesh filename="package://airbot/meshes/airbot_gripper_2/finger_left.STL"/>
      </geometry>
      <material name="">
        <color rgba="1 1 1 1"/>
      </material>
    </visual>
    <collision>
      <origin rpy="0 0 0" xyz="0 0 0"/>
      <geometry>
        <mesh filename="package://airbot/meshes/airbot_gripper_2/finger_left.STL"/>
      </geometry>
    </collision>
  </link>
  <joint name="endleft" type="prismatic">
    <origin rpy="3.14159 -1.5708 0" xyz="0 0.04 0"/>
    <parent link="gripper_base"/>
    <child link="finger_left"/>
    <axis xyz="0 1 0"/>
    <limit effort="0" lower="0" upper="0.04" velocity="0"/>
  </joint>
  <link name="finger_right">
    <inertial>
      <origin rpy="0 0 0" xyz="-0.048742 0.0096369 0.00044322"/>
      <mass value="0.0626"/>
      <inertia ixx="1.915E-05" ixy="1.343E-06" ixz="-6.8259E-07" iyy="2.7722E-05" iyz="2.0748E-07" izz="1.2248E-05"/>
    </inertial>
    <visual>
      <origin rpy="0 0 0" xyz="0 0 0"/>
      <geometry>
        <mesh filename="package://airbot/meshes/airbot_gripper_2/finger_right.STL"/>
      </geometry>
      <material name="">
        <color rgba="1 1 1 1"/>
      </material>
    </visual>
    <collision>
      <origin rpy="0 0 0" xyz="0 0 0"/>
      <geometry>
        <mesh filename="package://airbot/meshes/airbot_gripper_2/finger_right.STL"/>
      </geometry>
    </collision>
  </link>
   <joint name="endright" type="prismatic">
    <origin rpy="3.14159 -1.5708 0" xyz="0 -0.04 0"/>
    <parent link="gripper_base"/>
    <child link="finger_right"/>
    <axis xyz="0 1 0"/>
    <limit effort="0" lower="-0.04" upper="0" velocity="0"/> 
  </joint> -->
  <link name="end_link">
    <inertial>
      <origin rpy="0 0 0" xyz="0 0 0"/>
      <mass value="1E-15"/>
      <inertia ixx="1E-11" ixy="1E-15" ixz="1E-15" iyy="1E-11" iyz="1E-15" izz="1E-11"/>
    </inertial>
  </link>
  <joint name="joint_gripper_end" type="fixed">
    <origin rpy="3.141592 1.5708 0" xyz="0 0 0.02"/>
    <parent link="gripper_base"/>
    <child link="end_link"/>
  </joint>
</robot>