<mujoco model="airbot_play_v3_0_gripper">
   <option integrator="RK4" solver="Newton" />

  <compiler angle="radian" meshdir="meshes" eulerseq="zyx" autolimits="true" />

  <default>
    <joint limited="true" damping="0.5" armature="0.1" frictionloss="0.1" />
    <geom condim="4" contype="1" conaffinity="15" friction="0.9 0.2 0.2" solref="0.001 2" />
    <motor ctrllimited="true" />
    <equality solref="0.001 2" />
    <default class="visualgeom">
      <geom material="visualgeom" condim="1" contype="0" conaffinity="0" />
    </default>
  </default>
  <default>
    <default class="visual">
      <geom group="2" type="mesh" contype="0" conaffinity="0"/>
    </default>

    <default class='arm'>
      <default class='joint1'>
        <joint axis='0 0 1' range="-3.14 2.09" damping="0.2" frictionloss='15' />
        <position ctrlrange="-3.14 2.09"/>
      </default>

      <default class='joint2'>
        <joint axis='0 0 1' range="-2.96 0.17" damping="0.2" frictionloss='15' />
        <position ctrlrange="-2.96 0.17" />
      </default>

      <default class='joint3'>
        <joint axis='0 0 1' range='-0.087 3.14'  damping="0.2" frictionloss='15' />
        <position ctrlrange='-0.087 3.14'/>
      </default>

      <default class='joint4'>
        <joint axis='0 0 1' range="-2.96 2.96" damping="0.1" frictionloss='5' />
        <position ctrlrange="-2.96 2.96"/>
      </default>

      <default class='joint5'>
        <joint axis='0 0 1' range="-1.74 1.74"  damping="0.1" frictionloss='5' />
        <position ctrlrange="-1.74 1.74"/>
      </default>

      <default class='joint6'>
        <joint axis='0 0 1' range="-3.14 3.14"  damping="0.1" frictionloss='5' />
        <position ctrlrange="-3.14 3.14"/>
      </default>
    </default>

  </default>

  <statistic meansize="0.172126" extent="0.690271" center="0.0206251 -0.00105258 0.167563" />

  <asset>
    <mesh name="base_link" file="/home/yurong/下载/airbot_usd/urdf/airbot_play_v3_0_gripper/meshes/base_link.STL" />
    <mesh name="link1" file="/home/yurong/下载/airbot_usd/urdf/airbot_play_v3_0_gripper/meshes/link1.STL" />
    <mesh name="link2" file="/home/yurong/下载/airbot_usd/urdf/airbot_play_v3_0_gripper/meshes/link2.STL" />
    <mesh name="link3" file="/home/yurong/下载/airbot_usd/urdf/airbot_play_v3_0_gripper/meshes/link3.STL" />
    <mesh name="link4" file="/home/yurong/下载/airbot_usd/urdf/airbot_play_v3_0_gripper/meshes/link4.STL" />
    <mesh name="link5" file="/home/yurong/下载/airbot_usd/urdf/airbot_play_v3_0_gripper/meshes/link5.STL" />
    <mesh name="link6" file="/home/yurong/下载/airbot_usd/urdf/airbot_play_v3_0_gripper/meshes/link6.STL" />
    <texture name="texplane" type="2d" builtin="checker" rgb1=".2 .3 .4" rgb2=".1 0.15 0.2"
        width="512" height="512" mark="cross" markrgb=".8 .8 .8"/>
    <material name="matplane" reflectance="0." texture="texplane" texrepeat="1 1" texuniform="true" />
    <material name="visualgeom" rgba="0.5 0.9 0.2 1" />
  </asset>

  <worldbody>
    <light directional="true" diffuse="0.4 0.4 0.4" specular="0.1 0.1 0.1" pos="0 0 5.0" dir="0 0 -1" castshadow="false" />
    <light directional="true" diffuse="0.6 0.6 0.6" specular="0.2 0.2 0.2" pos="0 0 4" dir="0 0 -1" />
    <geom name="ground" type="plane" pos="0 0 0" size="100 100 0.001" quat="1 0 0 0" material="matplane" condim="3" conaffinity="15" />
    <camera name="fixed" pos="0 -3.0 0.5289457500277218" xyaxes="1 0 0 0 0 1" />
    <camera name="track" mode="trackcom" pos="0 -3.0 0.5289457500277218" xyaxes="1 0 0 0 0 1" />
    <body name="base_link">
      <inertial pos="-0.010729 -0.00017015 0.041712" quat="-0.0439975 0.724269 -0.0311603 0.687406" mass="0.77705" diaginertia="0.00124598 0.00118153 0.000844091" />
      <geom type="mesh" rgba="0.75294 0.75294 0.75294 1" mesh="base_link" contype="1" conaffinity="0" density="0" group="1" class="visualgeom" />
      <geom type="mesh" rgba="0.75294 0.75294 0.75294 1" mesh="base_link" />
      <body name="link1" pos="0 0 0.1172">
        <inertial pos="6.9854e-05 -0.0018033 -0.0040245" quat="0.714263 0.698988 0.0237953 -0.0260401" mass="0.5571" diaginertia="0.0003648 0.000344825 0.000294376" />
        <joint name="joint1" pos="0 0 0" axis="0 0 1" range="-3.14 2.09" />
        <geom type="mesh" rgba="0.89804 0.91765 0.92941 1" mesh="link1" contype="1" conaffinity="0" density="0" group="1" class="visualgeom" />
        <geom type="mesh" rgba="0.89804 0.91765 0.92941 1" mesh="link1" />
        <body name="link2" quat="0.135866 0.135867 -0.69393 0.693932">
          <inertial pos="0.22493 0.0047721 0.008023" quat="0.298115 0.596337 0.297303 0.683462" mass="0.64621" diaginertia="0.00516535 0.00505042 0.000418626" />
          <joint name="joint2" pos="0 0 0" axis="0 0 1" range="-2.96 0.17" />
          <geom type="mesh" rgba="0.75294 0.75294 0.75294 1" mesh="link2" contype="1" conaffinity="0" density="0" group="1" class="visualgeom" />
          <geom type="mesh" rgba="0.75294 0.75294 0.75294 1" mesh="link2" />
          <body name="link3" pos="0.27009 0 0" quat="0.55806 0 0 0.8298">
            <inertial pos="-0.00037204 0.16316 0.0024748" quat="0.694601 0.719377 -0.00121456 0.00500828" mass="0.28804" diaginertia="0.00261618 0.00255446 0.000219265" />
            <joint name="joint3" pos="0 0 0" axis="0 0 1" range="-0.087 3.14" />
            <geom type="mesh" rgba="0.75294 0.75294 0.75294 1" mesh="link3" contype="1" conaffinity="0" density="0" group="1" class="visualgeom" />
            <geom type="mesh" rgba="0.75294 0.75294 0.75294 1" mesh="link3" />
            <body name="link4" pos="0 0.30854 0" quat="0.499998 -0.5 -0.5 -0.500002">
              <inertial pos="5.2436e-06 0.00040412 -0.03228" quat="0.706226 0.0121253 0.00732967 0.707845" mass="0.34876" diaginertia="0.00505892 0.00498531 0.000346573" />
              <joint name="joint4" pos="0 0 0" axis="0 0 1" range="-2.96 2.96" />
              <geom type="mesh" rgba="1 1 1 1" mesh="link4" contype="1" conaffinity="0" density="0" group="1" class="visualgeom" />
              <geom type="mesh" rgba="1 1 1 1" mesh="link4" />
              <body name="link5" quat="0.707105 0.707108 0 0">
                <inertial pos="8.333e-06 0.026148 0.002525" quat="0.659447 0.751751 0 0" mass="0.36132" diaginertia="0.0004677 0.000432922 0.000178178" />
                <joint name="joint5" pos="0 0 0" axis="0 0 1" range="-1.74 1.74" />
                <geom type="mesh" rgba="0.89804 0.91765 0.92941 1" mesh="link5" contype="1" conaffinity="0" density="0" group="1" class="visualgeom" />
                <geom type="mesh" rgba="0.89804 0.91765 0.92941 1" mesh="link5" />
                <body name="link6" pos="0 0.26145 0" quat="0.707105 -0.707108 0 0">
                  <inertial pos="1.9522e-06 -0.002582 -0.13382" quat="0.971225 0.238158 -0.00132359 0.000401994" mass="0.65361" diaginertia="0.00295611 0.00264466 0.00205704" />
                  <joint name="joint6" pos="0 0 0" axis="0 0 1" range="-3.14 3.14" />
                  <geom type="mesh" rgba="0.69804 0.69804 0.69804 1" mesh="link6" contype="1" conaffinity="0" density="0" group="1" class="visualgeom" />
                  <geom type="mesh" rgba="0.69804 0.69804 0.69804 1" mesh="link6" />
                </body>
              </body>
            </body>
          </body>
        </body>
      </body>
    </body>
            <!-- Target object -->
    <body name="target" mocap="true">
      <geom name="target_geom" type="sphere" size="0.03" rgba="1 0 0 1" contype="0" conaffinity="0" />
    </body>

    
  </worldbody>

  <actuator>
  <position name="joint1" ctrllimited="true" ctrlrange="-3.14 2.09"  joint="joint1" kp="1000" user="1" forcelimited="true" forcerange="-300 300"/>
  <position name="joint2" ctrllimited="true" ctrlrange="-2.96 0.17"  joint="joint2" kp="1000" user="1" forcelimited="true" forcerange="-300 300"/>
  <position name="joint3" ctrllimited="true" ctrlrange="-0.087 3.14" joint="joint3" kp="1000" user="1" forcelimited="true" forcerange="-300 300"/>
  <position name="joint4" ctrllimited="true" ctrlrange="-2.96 2.96"  joint="joint4" kp="350" user="1" forcelimited="true" forcerange="-300 300"/>
  <position name="joint5" ctrllimited="true" ctrlrange="-1.74 1.74"  joint="joint5" kp="350" user="1" forcelimited="true" forcerange="-300 300"/>
  <position name="joint6" ctrllimited="true" ctrlrange="-3.14 3.14"  joint="joint6" kp="100" user="1" forcelimited="true" forcerange="-300 300"/>
  </actuator>

  <sensor>
  <jointpos name="joint1_pos" joint="joint1" />
  <jointpos name="joint2_pos" joint="joint2" />
  <jointpos name="joint3_pos" joint="joint3" />
  <jointpos name="joint4_pos" joint="joint4" />
  <jointpos name="joint5_pos" joint="joint5" />
  <jointpos name="joint6_pos" joint="joint6" />

  <jointvel name="joint1_vel" joint="joint1" />
  <jointvel name="joint2_vel" joint="joint2" />
  <jointvel name="joint3_vel" joint="joint3" />
  <jointvel name="joint4_vel" joint="joint4" />
  <jointvel name="joint5_vel" joint="joint5" />
  <jointvel name="joint6_vel" joint="joint6" />

  <!-- <jointactuatorfrc name="joint1_torque" joint="joint1" />
  <jointactuatorfrc name="joint2_torque" joint="joint2" />
  <jointactuatorfrc name="joint3_torque" joint="joint3" />
  <jointactuatorfrc name="joint4_torque" joint="joint4" />
  <jointactuatorfrc name="joint5_torque" joint="joint5" />
  <jointactuatorfrc name="joint6_torque" joint="joint6" /> -->

  <!-- <framepos name="endpoint_pos" objtype="site" objname="endpoint" reftype="body" refname="arm_base"/>
  <framequat name="endpoint_quat" objtype="site" objname="endpoint" reftype="body" refname="arm_base"/>
  <framelinvel name="endpoint_vel" objtype="site" objname="endpoint" reftype="body" refname="arm_base"/>
  <gyro name="endpoint_gyro" site="endpoint"/>
  <accelerometer name="endpoint_acc" site="endpoint" /> -->
  </sensor>
  
</mujoco>