
<mujoco model="airbot_play">
  <compiler angle="radian" meshdir="/home/yurong/workspace/airbot/meshes/airbot_play_v2_1/" autolimits="true"/>

  <asset>
      <texture type="skybox" builtin="gradient" rgb1="0.3 0.5 0.7" rgb2="0 0 0" width="512" height="512"/>
    <texture name="texplane" type="2d" builtin="checker" rgb1=".2 .3 .4" rgb2=".1 0.15 0.2"
        width="512" height="512" mark="cross" markrgb=".8 .8 .8"/>
    <texture name="texplane2" type="2d" builtin="checker" rgb1="1 0.3137 0.1843" rgb2="0.0 0.30196 0.38039"
        width="512" height="512" mark="cross" markrgb=".8 .8 .8"/>

    <material name="matplane" reflectance="0." texture="texplane" texrepeat="1 1" texuniform="true"/>
    <material name="matplane2" reflectance="0.1" texture="texplane2" texrepeat="1 1" texuniform="true"/>

    <material name='obstacle'  rgba='0.9 0.6 0.2 1'/>
    <material name='visualgeom'  rgba='0.5 0.9 0.2 1'/>
    <material name='visualgeom2'  rgba='0.5 0.9 0.2 1'/>

    <mesh name="base_link" file="base_link.STL"/>
    <mesh name="link1" file="link1.STL"/>
    <mesh name="link2" file="link2.STL"/>
    <mesh name="link3" file="link3.STL"/>
    <mesh name="link4" file="link4.STL"/>
    <mesh name="link5" file="link5.STL"/>
    <mesh name="gripper_base" file="gripper_base.STL"/>
    <mesh name="finger_left" file="finger_left.STL"/>
    <mesh name="finger_right" file="finger_right.STL"/>
  </asset>

  <worldbody>

    <light directional="true" diffuse=".4 .4 .4" specular="0.1 0.1 0.1" pos="0 0 5.0" dir="0 0 -1" castshadow="false"/>
    <light directional="true" diffuse=".6 .6 .6" specular="0.2 0.2 0.2" pos="0 0 4" dir="0 0 -1"/>
    <geom name="ground" type="plane" size="0 0 1" pos="0.001 0 0" quat="1 0 0 0" material="matplane" condim="1" conaffinity='15'/>

    <geom type="mesh" contype="0" conaffinity="0" group="1" density="0" rgba="0.75294 0.75294 0.75294 1" mesh="base_link"/>
    <geom type="mesh" rgba="0.75294 0.75294 0.75294 1" mesh="base_link"/>
    <body name="link1" pos="0 0 0.1172">
      <inertial pos="7.9126e-05 -0.002527 -0.0041359" quat="0.696716 0.716558 0.0238919 -0.0236876" mass="0.5571" diaginertia="0.000346294 0.000325437 0.000286269"/>
      <joint name="joint1" pos="0 0 0" axis="0 0 1" limited="true" range="-3.14 2.09" />
      <geom type="mesh" contype="0" conaffinity="0" group="1" density="0" rgba="0.89804 0.91765 0.92941 1" mesh="link1"/>
      <geom type="mesh" rgba="0.89804 0.91765 0.92941 1" mesh="link1"/>
      <body name="link2" quat="0.135866 0.135867 -0.69393 0.693932">
        <inertial pos="0.22493 0.0047721 0.008023" quat="0.570131 0.481429 0.43869 0.500729" mass="0.64621" diaginertia="0.00249324 0.00249324 0.00249324"/>
        <joint name="joint2" pos="0 0 0" axis="0 0 1" limited="true" range="-2.96 0.17" />
        <geom type="mesh" contype="0" conaffinity="0" group="1" density="0" rgba="0.75294 0.75294 0.75294 1" mesh="link2"/>
        <geom type="mesh" rgba="0.75294 0.75294 0.75294 1" mesh="link2"/>
        <body name="link3" pos="0.27009 0 0" quat="0.192193 0 0 -0.981357">
          <inertial pos="0.20055 -5.5576e-05 0.0019184" quat="0.560296 0.430899 0.431241 0.560737" mass="0.44556" diaginertia="0.0006727 0.000642497 0.000133452"/>
          <joint name="joint3" pos="0 0 0" axis="0 0 1" limited="true" range="-0.087 3.14" />
          <geom type="mesh" contype="0" conaffinity="0" group="1" density="0" rgba="0.75294 0.75294 0.75294 1" mesh="link3"/>
          <geom type="mesh" rgba="0.75294 0.75294 0.75294 1" mesh="link3"/>
          <body name="link4" pos="0.30854 0 0" quat="-2.59734e-06 0.707105 2.59735e-06 0.707108">
            <inertial pos="0.0015 0.00040412 -0.002328" quat="0.701888 0.712243 -0.00556124 0.00563957" mass="0.345876" diaginertia="0.000223467 0.000223467 0.000223467"/>
            <joint name="joint4" pos="0 0 0" axis="0 0 -1" limited="true" range="-2.96 2.96"  />
            <geom type="mesh" contype="0" conaffinity="0" group="1" density="0" rgba="1 1 1 1" mesh="link4"/>
            <geom type="mesh" rgba="1 1 1 1" mesh="link4"/>
            <body name="link5" quat="0.707105 0.707108 0 0">
              <inertial pos="8.3328e-06 0.026148 0.002525" quat="0.531568 0.4663 0.4663 0.531568" mass="0.186636" diaginertia="0.0004677 0.000432922 0.000178178"/>
              <joint name="joint5" pos="0 0 0" axis="0 0 -1" limited="true" range="-1.74 1.74"  />
              <geom type="mesh" contype="0" conaffinity="0" group="1" density="0" rgba="0.89804 0.91765 0.92941 1" mesh="link5"/>
              <geom type="mesh" rgba="0.89804 0.91765 0.92941 1" mesh="link5"/>
                <site name="ee_site" pos="0 0.23645 0" size="0.01" type="sphere" rgba="1 0 0 1"/>
              <body name="gripper_base" pos="0 0.23645 0" quat="0.499998 -0.5 0.5 0.500002">
                <inertial pos="0.020482 2.5483e-05 -0.079685" mass="0.40081" diaginertia="0.00109963 0.00109963 0.00109963"/>
                <joint name="joint6" pos="0 0 0" axis="0 0 -1" limited="true" range="-3.14 3.14"  />
                <geom type="mesh" contype="0" conaffinity="0" group="1" density="0" rgba="0.69804 0.69804 0.69804 1" mesh="gripper_base"/>
                <geom type="mesh" rgba="0.69804 0.69804 0.69804 1" mesh="gripper_base"/>
                <!-- <body name="finger_left" pos="0 0.04 0" quat="9.38184e-07 0.707105 -9.38187e-07 0.707108">
                  <inertial pos="-0.049039 -0.0096764 0.00038868" quat="0.650491 0.0296695 0.0398251 0.757889" mass="0.061803" diaginertia="2.74809e-05 1.88104e-05 1.19127e-05"/>
                  <joint name="endleft" pos="0 0 0" axis="0 1 0" type="slide" limited="true" range="0 0.04"/>
                  <geom type="mesh" contype="0" conaffinity="0" group="1" density="0" rgba="1 1 1 1" mesh="finger_left"/>
                  <geom type="mesh" rgba="1 1 1 1" mesh="finger_left"/>
                </body>
                <body name="finger_right" pos="0 -0.04 0" quat="9.38184e-07 0.707105 -9.38187e-07 0.707108">
                  <inertial pos="-0.048742 0.0096369 0.00044322" quat="0.757393 0.0415116 0.0313705 0.650883" mass="0.0626" diaginertia="2.79281e-05 1.90181e-05 1.21737e-05"/>
                  <joint name="endright" pos="0 0 0" axis="0 1 0" type="slide" limited="true" range="-0.04 0"/>
                  <geom type="mesh" contype="0" conaffinity="0" group="1" density="0" rgba="1 1 1 1" mesh="finger_right"/>
                  <geom type="mesh" rgba="1 1 1 1" mesh="finger_right"/>
                </body> -->
              </body>
            </body>
          </body>
        </body>
      </body>
    </body>
  </worldbody>
  <actuator>
    <motor name="joint1" joint="joint1" gear="1" ctrllimited="true" ctrlrange="-200 200"/>
    <motor name="joint2" joint="joint2" gear="1" ctrllimited="true" ctrlrange="-200 200"/>
    <motor name="joint3" joint="joint3" gear="1" ctrllimited="true" ctrlrange="-200 200"/>
    <motor name="joint4" joint="joint4" gear="1" ctrllimited="true" ctrlrange="-200 200"/>
    <motor name="joint5" joint="joint5" gear="1" ctrllimited="true" ctrlrange="-200 200"/>
    <motor name="joint6" joint="joint6" gear="1" ctrllimited="true" ctrlrange="-200 200"/>

  </actuator>


</mujoco>
